<?xml version="1.0" ?>
<!-- =================================================================================== -->
<!-- |    This document was autogenerated by xacro from bigman.urdf.xacro              | -->
<!-- |    EDITING THIS FILE BY HAND IS NOT RECOMMENDED                                 | -->
<!-- =================================================================================== -->
<robot name="bigman" xmlns:xacro="http://ros.org/wiki/xacro">
  <!-- 
  ROS urdf definition of the BIGMAN humanoid robot by Istituto Italiano di Tecnologia
  
  DO NOT INCLUDE THIS FILE DIRECTLY! USE bigman_robot.urdf.xacro INSTEAD!

  Author: Enrico Mingo & Alessio Rocchi

  Inertial matrix has to be in CoM frame (URDF specs)

  Velocity and effort limits are fake!
-->
  <!-- ************ MODEL CONFIGURATION ************ -->
  <!--
####################################################
##
##  BIGMAN_UPPER_BODY
##  if "true" the kinematic chains of the arms and torso 
##  will be used to generate the model
##
####################################################
-->
  <!--
####################################################
##
##  BIGMAN_LEGS
##  if "true" the kinematic chains of the legs
##  will be used to generate the model
##
####################################################
-->
  <!--
####################################################
##
##  BIGMAN_OLD_CHEST
##  if "true" the old version of the chest will be
##  used.
##  
##
####################################################
-->
  <!--
####################################################
##
##  BIGMAN_FIXED_HANDS
##  if "true" a fixed joint between wrist and hand 
##  will be used otherwise a rotative joints will
##  be used.
##  
##
####################################################
-->
  <!--
####################################################
##
##  BIGMAN_FIXED_MULTISENSE
##  if "true" a fixed joint between "head" and 
##  "hokuyo_link" will be used otherwise a continuous 
##  joints will be used.
##  
##
####################################################
-->
  <!--
####################################################
##
##  BIGMAN_HEAD
##  if "true" a fixed joint between "NeckPitch" and
##  "head" will be used to connect the head to the rest
##  of the body. If "false" the head will not be added 
##  to the model (this is the case when the multisense
##  from the launch file is used). 
##  
##
####################################################
-->
  <!--
####################################################
##
##  BIGMAN_ADD_PROTECTIONS
##  if "true" the protections are added to the model.
##  
##
####################################################
-->
  <!--
####################################################
##
##  BIGMAN_ADD_BACKPACK
##  if "true" the backpack is added to the model.
##  
##
####################################################
-->
  <!--
####################################################
##
##  BIGMAN_ADD_RAISING_SUPPORT
##  if "true" the raising support are added to the model.
##  
##
####################################################
-->
  <!--
####################################################
##
##  BIGMAN_NEW_FEET
##  if "true" the new feet with the joint in the middle
##  are used to the model.
##  
##
####################################################
-->
  <!--
####################################################
##
##  BIGMAN_SAFETY_JOINT_LIMITS_X
##  if "true" the more strict joint limits are used 
##  for the X part
##  
##
####################################################
-->
  <!-- ***********  MODEL COLORS *********** -->
  <material name="grey">
    <color rgba="0.5 0.5 0.5 1"/>
  </material>
  <material name="dark_grey">
    <color rgba="0.3 0.3 0.3 1"/>
  </material>
  <material name="blue">
    <color rgba="0.0 0.2 0.3 1"/>
  </material>
  <!-- ************ BIGMAN BASE ************** -->
  <!-- 
  ROS urdf definition of the BIGMAN humanoid robot by Istituto Italiano di Tecnologia
  
  DO NOT INCLUDE THIS FILE DIRECTLY! USE bigman_robot.urdf.xacro INSTEAD!

  Author: Enrico Mingo & Alessio Rocchi

  Inertial matrix has to be in CoM frame (URDF specs)

  Velocity and effort limits are fake!
-->
  <!--
The coordinate frame called base_link is rigidly attached to the robot root body. It is recommended to choose the robot waist as its root body. The base_link can be attached to the root in any arbitrary position or orientation; for every hardware platform there will be a different place on the base that provides an obvious point of reference. Note that REP 103 [1] specifies a preferred orientation for frames. -->
  <link name="base_link"/>
  <link name="Waist">
    <inertial>
      <origin rpy="0.0 0.0 0.0" xyz="-0.022813402 -0.00073935443 0.030422909"/>
      <mass value="1.1046081e+01"/>
      <inertia ixx="0.096207978" ixy="0.00014081043" ixz="0.0031258127" iyy="0.098511158" iyz="0.00013938149" izz="0.086541531"/>
    </inertial>
    <visual>
      <origin rpy="0 0 0" xyz="0 0 0"/>
      <geometry name="Waist_visual">
        <mesh filename="package://bigman_urdf/meshes/Waist.STL" scale="0.001 0.001 0.001"/>
      </geometry>
      <material name="grey"/>
    </visual>
    <collision>
      <origin rpy="0 0 0" xyz="0 0 0"/>
      <geometry name="Waist_collision">
        <mesh filename="package://bigman_urdf/meshes/simple/Waist.STL" scale="0.001 0.001 0.001"/>
      </geometry>
    </collision>
  </link>
  <joint name="base_joint" type="fixed">
    <parent link="base_link"/>
    <child link="Waist"/>
    <origin rpy="0 0 0" xyz="0 0 0"/>
  </joint>
  <!-- ********************ARMS******************** -->
  <!-- LINKS -->
  <!-- LEFT ARM -->
  <link name="LShp">
    <inertial>
      <origin rpy="0 0 0" xyz="-0.00543349 0.04480023 0.01581062"/>
      <mass value="1.81745527"/>
      <inertia ixx="0.00571053" ixy="-0.00041083" ixz="-0.00005130" iyy="0.01126908" iyz="0.00003461" izz="0.01371197"/>
    </inertial>
    <visual>
      <origin rpy="0 0 0" xyz="0 0 0"/>
      <geometry name="LShp_visual">
        <mesh filename="package://bigman_urdf/meshes/ShoulderPitch.STL" scale="0.001 -0.001 0.001"/>
      </geometry>
      <material name="dark_grey"/>
    </visual>
    <collision>
      <origin rpy="0 0 0" xyz="0 0 0"/>
      <geometry name="LShp_collision">
        <mesh filename="package://bigman_urdf/meshes/simple/ShoulderPitch.STL" scale="0.001 -0.001 0.001"/>
      </geometry>
    </collision>
  </link>
  <link name="LShr">
    <inertial>
      <origin rpy="0 0 0" xyz="0.00729315 -0.00002698 -0.07529696"/>
      <mass value="5.00486460"/>
      <inertia ixx="0.01644345" ixy="0.00001187" ixz="-0.00010546" iyy="0.01804804" iyz="0.00000565" izz="0.00802420"/>
    </inertial>
    <visual>
      <origin rpy="0 0 0" xyz="0 0 0"/>
      <geometry name="LShr_visual">
        <mesh filename="package://bigman_urdf/meshes/TopUpperArm.STL" scale="0.001 -0.001 0.001"/>
      </geometry>
      <material name="dark_grey"/>
    </visual>
    <collision>
      <origin rpy="0 0 0" xyz="0 0 0"/>
      <geometry name="LShr_collision">
        <mesh filename="package://bigman_urdf/meshes/simple/TopUpperArm.STL" scale="0.001 -0.001 0.001"/>
      </geometry>
    </collision>
  </link>
  <link name="LShy">
    <inertial>
      <origin rpy="0 0 0" xyz="0.02765373 0.03258647 -0.12698781"/>
      <mass value="3.20289133"/>
      <inertia ixx="0.01129046" ixy="-0.00013518" ixz="-0.00134760" iyy="0.00984951" iyz="0.00026836" izz="0.00728549"/>
    </inertial>
    <visual>
      <origin rpy="0 0 0" xyz="0 0 0"/>
      <geometry name="LShy_visual">
        <mesh filename="package://bigman_urdf/meshes/BottomUpperArm.STL" scale="0.001 -0.001 0.001"/>
      </geometry>
      <material name="dark_grey"/>
    </visual>
    <collision>
      <origin rpy="0 0 0" xyz="0 0 0"/>
      <geometry name="LShy_collision">
        <mesh filename="package://bigman_urdf/meshes/simple/BottomUpperArm.STL" scale="0.001 -0.001 0.001"/>
      </geometry>
    </collision>
  </link>
  <link name="LElb">
    <inertial>
      <origin rpy="0 0 0" xyz="-0.055754915 0.007582604 -0.043820396"/>
      <mass value="8.6765385e-01"/>
      <inertia ixx="0.0040395238" ixy="-0.00034973136" ixz="-0.00068400465" iyy="0.0022460561" iyz="-0.00028844444" izz="0.0044895027"/>
    </inertial>
    <visual>
      <origin rpy="0 0 0" xyz="0 0 0"/>
      <geometry name="LElb_visual">
        <mesh filename="package://bigman_urdf/meshes/Elbow.STL" scale="0.001 -0.001 0.001"/>
      </geometry>
      <material name="dark_grey"/>
    </visual>
    <collision>
      <origin rpy="0 0 0" xyz="0 0 0"/>
      <geometry name="LElb_collision">
        <mesh filename="package://bigman_urdf/meshes/simple/Elbow.STL" scale="0.001 -0.001 0.001"/>
      </geometry>
    </collision>
  </link>
  <!-- JOINTS -->
  <!-- LEFT ARM -->
  <joint name="LShSag" type="revolute">
    <parent link="Waist"/>
    <child link="LShp"/>
    <origin rpy="0 0 -0.3491" xyz="0.045646 0.219164 0.001531"/>
    <axis xyz="0.0 0.743144825 0.669130606"/>
    <limit effort="120" lower="-2.87979326578" upper="2.79252680318" velocity="6.283"/>
    <dynamics damping="3.0" friction="0"/>
  </joint>
  <joint name="LShLat" type="revolute">
    <parent link="LShp"/>
    <child link="LShr"/>
    <origin rpy="0 0 0" xyz="0.0 0.116568264 0.03364"/>
    <axis xyz="1 0 0"/>
    <limit effort="120" lower="0.0872664625995" upper="3.8571776469" velocity="6.283"/>
    <dynamics damping="3.0" friction="0"/>
  </joint>
  <joint name="LShYaw" type="revolute">
    <parent link="LShr"/>
    <child link="LShy"/>
    <origin rpy="0 0 0" xyz="0.0 0.0 -0.222"/>
    <axis xyz="0 0 1"/>
    <limit effort="120" lower="-2.84488668074" upper="2.84488668074" velocity="6.283"/>
    <dynamics damping="3.0" friction="0"/>
  </joint>
  <joint name="LElbj" type="revolute">
    <parent link="LShy"/>
    <child link="LElb"/>
    <origin rpy="0 0 0" xyz="0.036 0.0 -0.15"/>
    <axis xyz="0 1 0"/>
    <limit effort="60" lower="-2.96705972838" upper="0.593411945677" velocity="6.283"/>
    <dynamics damping="3.0" friction="0"/>
  </joint>
  <link name="l_arm_ft"/>
  <joint name="l_arm_ft_joint" type="fixed">
    <parent link="LWrMot3"/>
    <child link="l_arm_ft"/>
    <origin rpy="0 0 0" xyz="0 0 -0.0565"/>
  </joint>
  <!-- ************ FOREARMS ************ -->
  <!-- This links are defined in order to be compliant with http://www.ros.org/reps/rep-0120.html#coordinate-frames
	and to define the end effectors of the robot -->
  <!-- position and orientation of the arm regardless of the tool (grasping device for instance) attached to it -->
  <link name="l_wrist"/>
  <!-- ****************LINKS**************** -->
  <!-- ****************LEFT FOREARM**************** -->
  <link name="LForearm">
    <inertial>
      <origin rpy="0 0 0" xyz="1.2625599e-05 0.0042975381 0.044717986"/>
      <mass value="2.2127686"/>
      <inertia ixx="0.0065428368" ixy="-4.1196967e-05" ixz="3.272727e-06" iyy="0.005587829" iyz="0.00042088668" izz="0.0024783023"/>
    </inertial>
    <visual>
      <origin rpy="0 0 0" xyz="0 0 0"/>
      <geometry name="LForearm_visual">
        <mesh filename="package://bigman_urdf/meshes/Forearm.STL" scale="0.001 -0.001 0.001"/>
      </geometry>
      <material name="dark_grey"/>
    </visual>
    <collision>
      <origin rpy="0 0 0" xyz="0 0 0"/>
      <geometry name="LForearm_collision">
        <mesh filename="package://bigman_urdf/meshes/simple/Forearm.STL" scale="0.001 -0.001 0.001"/>
      </geometry>
    </collision>
  </link>
  <link name="LWrMot2">
    <inertial>
      <origin rpy="0 0 0" xyz="0.009819377 0.0013797184 -0.080380065"/>
      <mass value="1.2838072"/>
      <inertia ixx="0.001994124" ixy="2.569706e-05" ixz="0.00017443538" iyy="0.0021755329" iyz="-0.00012100987" izz="0.001830376"/>
    </inertial>
    <visual>
      <origin rpy="0 0 0" xyz="0 0 0"/>
      <geometry name="LWrMot2_visual">
        <mesh filename="package://bigman_urdf/meshes/ForearmPitch.STL" scale="0.001 -0.001 0.001"/>
      </geometry>
      <material name="dark_grey"/>
    </visual>
    <collision>
      <origin rpy="0 0 0" xyz="0 0 0"/>
      <geometry name="LWrMot2_collision">
        <mesh filename="package://bigman_urdf/meshes/simple/ForearmPitch.STL" scale="0.001 -0.001 0.001"/>
      </geometry>
    </collision>
  </link>
  <link name="LWrMot3">
    <inertial>
      <origin rpy="0 0 0" xyz="0.0070380706 -1.0811188e-05 -0.039669274"/>
      <mass value="4.2801447e-01"/>
      <inertia ixx="0.00028620156" ixy="5.2570457e-08" ixz="-3.9174213e-05" iyy="0.00071261855" iyz="-9.5020266e-08" izz="0.00061444258"/>
    </inertial>
    <visual>
      <origin rpy="0 0 0" xyz="0 0 0"/>
      <geometry name="LWrMot3_visual">
        <mesh filename="package://bigman_urdf/meshes/ForearmRoll.STL" scale="0.001 -0.001 0.001"/>
      </geometry>
      <material name="blue"/>
    </visual>
    <collision>
      <origin rpy="0 0 0" xyz="0 0 0"/>
      <geometry name="LWrMot3_collision">
        <mesh filename="package://bigman_urdf/meshes/simple/ForearmRoll.STL" scale="0.001 -0.001 0.001"/>
      </geometry>
    </collision>
  </link>
  <!-- ****************JOINTS**************** -->
  <!-- ****************LEFT FOREARM**************** -->
  <joint name="LForearmPlate" type="revolute">
    <parent link="LElb"/>
    <child link="LForearm"/>
    <origin rpy="0 0 0" xyz="-0.075 0.0 -0.1955"/>
    <axis xyz="0 0 1"/>
    <limit effort="60" lower="-2.529" upper="2.529" velocity="6.283"/>
    <dynamics damping="0.03" friction="0"/>
  </joint>
  <joint name="LWrj1" type="revolute">
    <parent link="LForearm"/>
    <child link="LWrMot2"/>
    <origin rpy="0 0 0" xyz="0 0 0"/>
    <axis xyz="0 1 0"/>
    <limit effort="60" lower="-1.48" upper="1.48" velocity="6.283"/>
    <dynamics damping="0.03" friction="0"/>
  </joint>
  <joint name="LWrj2" type="revolute">
    <parent link="LWrMot2"/>
    <child link="LWrMot3"/>
    <origin rpy="0 0 0" xyz="0 0 -0.092"/>
    <axis xyz="1 0 0"/>
    <limit effort="60" lower="-1.48" upper="1.48" velocity="6.283"/>
    <dynamics damping="0.03" friction="0"/>
  </joint>
  <joint name="l_wrist_joint" type="fixed">
    <parent link="LWrMot3"/>
    <child link="l_wrist"/>
    <origin rpy="0 0 0" xyz="0 0 0"/>
  </joint>
  <!-- ************ HANDS ************ -->
  <!-- For the hand we use the inertia of a parallelepiped -->
  <!-- LINKS -->
  <link name="LSoftHand"/>
  <link name="LSoftHandLink">
    <inertial>
      <origin rpy="0 0 0" xyz="0 0 -0.17"/>
      <mass value="1.2"/>
      <inertia ixx="0.00232" ixy="0" ixz="0" iyy="0.00296" iyz="0" izz="0.00136"/>
    </inertial>
    <visual>
      <origin rpy="0.0 0.0 0.0" xyz="0.0 0.0 0.0"/>
      <geometry name="LSoftHandLink_visual">
        <mesh filename="package://bigman_urdf/meshes/SoftHandOpen.STL" scale="0.001 -0.001 0.001"/>
      </geometry>
      <material name="grey"/>
    </visual>
    <collision>
      <origin rpy="0.0 0.0 0.0" xyz="0.0 0.0 0.0"/>
      <geometry name="LSoftHandLink_collision">
        <mesh filename="package://bigman_urdf/meshes/simple/SoftHandOpen.STL" scale="0.001 -0.001 0.001"/>
      </geometry>
    </collision>
  </link>
  <!-- JOINTS -->
  <joint name="l_handj" type="fixed">
    <parent link="LWrMot3"/>
    <child link="LSoftHandLink"/>
    <origin rpy="0 0 0" xyz="0 0 0"/>
  </joint>
  <joint name="l_handj2" type="fixed">
    <parent link="LSoftHandLink"/>
    <child link="LSoftHand"/>
    <origin rpy="0 0 0" xyz="0 -0.0305 -0.21"/>
  </joint>
</robot>

