<?xml version="1.0" ?>
<robot name="centauro" xmlns:xacro="http://www.ros.org/wiki/xacro">
  <!-- config -->
  <!--
<xacro:property name="ARMS" value="true"/>
<xacro:property name="TORSO" value="true" />
<xacro:property name="ARM_ACTUATORS" value="true"/> 
<xacro:property name="LEGS" value="true"/>
<xacro:property name="LEG_ACTUATORS" value="true"/>

<xacro:property name="TORSO_ACTUATORS" value="true"/>
<xacro:property name="WHEELS" value="true"/>
<xacro:property name="WHEELS_ACTUATORS" value="true"/>-->
  <!-- /config -->
  <!-- /constants -->
  <gazebo>
    <plugin filename="libgazebo_ros_control.so" name="gazebo_ros_control">
      <robotNamespace>/centauro</robotNamespace>
      <robotSimType>gazebo_ros_control/DefaultRobotHWSim</robotSimType>
    </plugin>
  </gazebo>
  <gazebo reference="knee_1">
    <sensor name="foot_contact_sensor_1" type="contact">
      <always_on>true</always_on>
      <update_rate>1000.0</update_rate>
      <contact>
        <collision>knee_1_collision_1</collision>
      </contact>
      <plugin filename="libgazebo_ros_bumper.so" name="bumper_1">
        <bumperTopicName>raw_contacts_foot_1</bumperTopicName>
        <frameName>knee_1</frameName>
      </plugin>
    </sensor>
  </gazebo>
  <gazebo reference="knee_2">
    <sensor name="foot_contact_sensor_2" type="contact">
      <always_on>true</always_on>
      <update_rate>1000.0</update_rate>
      <contact>
        <collision>knee_2_collision_1</collision>
      </contact>
      <plugin filename="libgazebo_ros_bumper.so" name="bumper_2">
        <bumperTopicName>raw_contacts_foot_2</bumperTopicName>
        <frameName>knee_2</frameName>
      </plugin>
    </sensor>
  </gazebo>
  <gazebo reference="knee_3">
    <sensor name="foot_contact_sensor_3" type="contact">
      <always_on>true</always_on>
      <update_rate>1000.0</update_rate>
      <contact>
        <collision>knee_3_collision_1</collision>
      </contact>
      <plugin filename="libgazebo_ros_bumper.so" name="bumper_3">
        <bumperTopicName>raw_contacts_foot_3</bumperTopicName>
        <frameName>knee_3</frameName>
      </plugin>
    </sensor>
  </gazebo>
  <gazebo reference="knee_4">
    <sensor name="foot_contact_sensor_4" type="contact">
      <always_on>true</always_on>
      <update_rate>1000.0</update_rate>
      <contact>
        <collision>knee_4_collision_1</collision>
      </contact>
      <plugin filename="libgazebo_ros_bumper.so" name="bumper_4">
        <bumperTopicName>raw_contacts_foot_4</bumperTopicName>
        <frameName>knee_4</frameName>
      </plugin>
    </sensor>
  </gazebo>
  <!-- The ft_sensor plugin -->
  <!--<gazebo>
    <plugin name="ft_sensor" filename="libgazebo_ros_ft_sensor.so">
        <updateRate>100.0</updateRate>
        <topicName>ft_sensor_1</topicName>
        <jointName>foot_fixed_joint_1</jointName>
    </plugin>
</gazebo>-->
  <!-- The ft_sensor plugin -->
  <!--<gazebo>
    <plugin name="ft_sensor" filename="libgazebo_ros_ft_sensor.so">
        <updateRate>100.0</updateRate>
        <topicName>ft_sensor_2</topicName>
        <jointName>foot_fixed_joint_2</jointName>
    </plugin>
</gazebo>-->
  <!-- The ft_sensor plugin -->
  <!--<gazebo>
    <plugin name="ft_sensor" filename="libgazebo_ros_ft_sensor.so">
        <updateRate>100.0</updateRate>
        <topicName>ft_sensor_3</topicName>
        <jointName>foot_fixed_joint_3</jointName>
    </plugin>
</gazebo>-->
  <!-- The ft_sensor plugin -->
  <!--<gazebo>
    <plugin name="ft_sensor" filename="libgazebo_ros_ft_sensor.so">
        <updateRate>100.0</updateRate>
        <topicName>ft_sensor_4</topicName>
        <jointName>foot_fixed_joint_4</jointName>
    </plugin>
</gazebo>-->
  <gazebo reference="base_link">
    <material>Gazebo/Red</material>
  </gazebo>
  <gazebo reference="pelvis">
    <material>Gazebo/Blue</material>
    <mu1>1</mu1>
    <mu2>1</mu2>
  </gazebo>
  <gazebo reference="torso_1">
    <mu1>1</mu1>
    <mu2>1</mu2>
    <material>Gazebo/Grey</material>
  </gazebo>
  <gazebo reference="torso_2">
    <material>Gazebo/Blue</material>
    <mu1>1</mu1>
    <mu2>1</mu2>
  </gazebo>
  <gazebo reference="hip1_1">
    <material>Gazebo/Grey</material>
    <mu1>1</mu1>
    <mu2>1</mu2>
  </gazebo>
  <gazebo reference="hip1_2">
    <material>Gazebo/Grey</material>
    <mu1>1</mu1>
    <mu2>1</mu2>
  </gazebo>
  <gazebo reference="hip1_3">
    <material>Gazebo/Grey</material>
    <mu1>1</mu1>
    <mu2>1</mu2>
  </gazebo>
  <gazebo reference="hip1_4">
    <material>Gazebo/Grey</material>
    <mu1>1</mu1>
    <mu2>1</mu2>
  </gazebo>
  <gazebo reference="hip2_1">
    <material>Gazebo/Blue</material>
    <mu1>1</mu1>
    <mu2>1</mu2>
  </gazebo>
  <gazebo reference="hip2_2">
    <material>Gazebo/Blue</material>
    <mu1>1</mu1>
    <mu2>1</mu2>
  </gazebo>
  <gazebo reference="hip2_3">
    <material>Gazebo/Blue</material>
    <mu1>1</mu1>
    <mu2>1</mu2>
  </gazebo>
  <gazebo reference="hip2_4">
    <material>Gazebo/Blue</material>
    <mu1>1</mu1>
    <mu2>1</mu2>
  </gazebo>
  <gazebo reference="knee_1">
    <material>Gazebo/Grey</material>
    <mu1>10</mu1>
    <mu2>10</mu2>
  </gazebo>
  <gazebo reference="knee_2">
    <material>Gazebo/Grey</material>
    <mu1>10</mu1>
    <mu2>10</mu2>
  </gazebo>
  <gazebo reference="knee_3">
    <material>Gazebo/Grey</material>
    <mu1>10</mu1>
    <mu2>10</mu2>
  </gazebo>
  <gazebo reference="knee_4">
    <material>Gazebo/Grey</material>
    <mu1>10</mu1>
    <mu2>10</mu2>
  </gazebo>
  <gazebo reference="arm1_1">
    <material>Gazebo/Blue</material>
    <mu1>0</mu1>
    <mu2>0</mu2>
  </gazebo>
  <gazebo reference="arm2_1">
    <material>Gazebo/Blue</material>
    <mu1>0</mu1>
    <mu2>0</mu2>
  </gazebo>
  <gazebo reference="arm1_2">
    <material>Gazebo/Grey</material>
    <mu1>0</mu1>
    <mu2>0</mu2>
  </gazebo>
  <gazebo reference="arm2_2">
    <material>Gazebo/Grey</material>
    <mu1>0</mu1>
    <mu2>0</mu2>
  </gazebo>
  <gazebo reference="arm1_3">
    <material>Gazebo/Blue</material>
    <mu1>0</mu1>
    <mu2>0</mu2>
  </gazebo>
  <gazebo reference="arm2_3">
    <material>Gazebo/Blue</material>
    <mu1>0</mu1>
    <mu2>0</mu2>
  </gazebo>
  <gazebo reference="arm1_4">
    <material>Gazebo/Grey</material>
    <mu1>0</mu1>
    <mu2>0</mu2>
  </gazebo>
  <gazebo reference="arm2_4">
    <material>Gazebo/Grey</material>
    <mu1>0</mu1>
    <mu2>0</mu2>
  </gazebo>
  <gazebo reference="arm1_5">
    <material>Gazebo/Blue</material>
    <mu1>0</mu1>
    <mu2>0</mu2>
  </gazebo>
  <gazebo reference="arm2_5">
    <material>Gazebo/Blue</material>
    <mu1>0</mu1>
    <mu2>0</mu2>
  </gazebo>
  <gazebo reference="arm1_6">
    <material>Gazebo/Grey</material>
    <mu1>0</mu1>
    <mu2>0</mu2>
  </gazebo>
  <gazebo reference="arm2_6">
    <material>Gazebo/Grey</material>
    <mu1>0</mu1>
    <mu2>0</mu2>
  </gazebo>
  <gazebo reference="arm1_7">
    <material>Gazebo/Blue</material>
    <mu1>0</mu1>
    <mu2>0</mu2>
  </gazebo>
  <gazebo reference="arm2_7">
    <material>Gazebo/Blue</material>
    <mu1>0</mu1>
    <mu2>0</mu2>
  </gazebo>
  <gazebo reference="wheel_hip_1">
    <material>Gazebo/Black</material>
  </gazebo>
  <gazebo reference="wheel_hip_2">
    <material>Gazebo/Black</material>
  </gazebo>
  <gazebo reference="wheel_hip_3">
    <material>Gazebo/Black</material>
  </gazebo>
  <gazebo reference="wheel_hip_4">
    <material>Gazebo/Black</material>
  </gazebo>
  <gazebo reference="wheel_knee_1">
    <material>Gazebo/Black</material>
  </gazebo>
  <gazebo reference="wheel_knee_2">
    <material>Gazebo/Black</material>
  </gazebo>
  <gazebo reference="wheel_knee_3">
    <material>Gazebo/Black</material>
  </gazebo>
  <gazebo reference="wheel_knee_4">
    <material>Gazebo/Black</material>
  </gazebo>
  <material name="grey">
    <color rgba="0.5 0.5 0.5 1"/>
  </material>
  <material name="dark_grey">
    <color rgba="0.3 0.3 0.3 1"/>
  </material>
  <material name="blue">
    <color rgba="0.0 0.2 0.3 1"/>
  </material>
  <material name="red">
    <color rgba="0.5 0.1 0.2 1"/>
  </material>
  <material name="black">
    <color rgba="0.0 0.0 0.0 1"/>
  </material>
  <!-- /macro arms -->
  <!-- /other files -->
  <!-- reference -->
  <link name="world"/>
  <link name="pelvis">
    <inertial>
      <origin xyz="-0.0704 0.0 -0.0416"/>
      <!-- TODO -->
      <mass value="25.0"/>
      <!-- org: 25 -->
      <inertia ixx="0.242311" ixy="0.0" ixz="-0.233584" iyy="1.338707" iyz="0.0" izz="1.369479"/>
      <!-- TODO -->
    </inertial>
    <visual>
      <origin xyz="0 0 0"/>
      <!-- OK -->
      <geometry>
        <box size="0.70 0.40 0.20"/>
        <!-- OK -->
      </geometry>
      <material name="red"/>
    </visual>
    <!--	<collision>
		<origin xyz="0 0 0"/>
		<geometry>
			<box size="0.70 0.40 0.20"/>
		</geometry>
	</collision> -->
  </link>
  <joint name="reference" type="fixed">
    <origin xyz="0 0 0.85"/>
    <parent link="world"/>
    <child link="pelvis"/>
  </joint>
  <!-- torso links -->
  <!--<xacro:unless	value="$(arg ONE_ARM)">
<link name="torso_1">
<inertial>
		<origin xyz="${Torso_1_x} ${Torso_1_y} ${Torso_1_z}"/>
		<mass value="${Torso_1_mass}"/> 
		<inertia ixx="${Torso_1_xx}" ixy="${Torso_1_xy}" ixz="${Torso_1_xz}" iyy="${Torso_1_yy}" iyz="${Torso_1_yz}" izz="${Torso_1_zz}"/> 
	</inertial>
	
	<visual>
		<origin xyz="0.0 0 0.0"/>
		<geometry>
			<cylinder length="${motors_length}" radius="${motors_radius}"/>
		</geometry>
		<material name="grey"/>
	</visual>
	
	<visual>
		<origin xyz="0.0 0 ${0.25/2}"/>
		<geometry>
			<box size="${link_visual} ${link_visual} 0.25"/> 
		</geometry>
		<material name="grey"/>
	</visual>

	
	<collision>
		<origin xyz="0.0 0 0.0"/>
		<geometry>
			<cylinder length="${motors_length}" radius="${motors_radius}"/>
		</geometry>
		<material name="grey"/>
	</collision> 

</link>
</xacro:unless> -->
  <link name="torso_2">
    <inertial>
      <origin xyz="0.0 0.0 0.183333"/>
      <mass value="3.0"/>
      <!-- mass  7: torso_1 (2) + torso_2 (5), head un_modelled -->
      <inertia ixx="0.094335" ixy="8.5e-05" ixz="-3.1e-05" iyy="0.029946" iyz="1.7e-05" izz="0.068486"/>
      <!-- <inertia ixx="0.01" ixy="0.01" ixz="0.01" iyy="0.01" iyz="0.01" izz="0.01"/> -->
    </inertial>
    <visual>
      <origin xyz="0.0 0 0.20"/>
      <geometry>
        <box size="0.2 0.3 0.1"/>
      </geometry>
      <material name="blue"/>
    </visual>
    <visual>
      <origin xyz="0.0 0 0.0"/>
      <geometry>
        <cylinder length="0.1" radius="0.05"/>
      </geometry>
      <material name="grey"/>
    </visual>
    <!--	<collision>
		<origin xyz="0.0 0 0.05"/>
		<geometry>
			<box size="${0.2-collision} ${0.5-collision} ${0.1-collision}"/>
		</geometry>
		<material name="blue"/>
	</collision> -->
    <collision>
      <origin xyz="0.0 0 0.0"/>
      <geometry>
        <cylinder length="0.1" radius="0.05"/>
      </geometry>
      <material name="grey"/>
    </collision>
  </link>
  <!-- /torso links -->
  <joint name="torso_yaw" type="revolute">
    <parent link="pelvis"/>
    <child link="torso_2"/>
    <origin xyz="0.30 0 0"/>
    <axis xyz="0 0 1"/>
    <limit effort="350" lower="-2.618" upper="2.618" velocity="6.5"/>
    <!-- TODO -->
  </joint>
  <!-- /torso joints -->
  <transmission name="t_torso_yaw">
    <type> transmission_interface/SimpleTransmission</type>
    <joint name="torso_yaw">
      <hardwareInterface>EffortJointInterface</hardwareInterface>
    </joint>
    <actuator name="motor_torso_yaw">
      <hardwareInterface>EffortJointInterface</hardwareInterface>
      <machanicalReduction>1</machanicalReduction>
    </actuator>
    <robotNamespace>/centauro</robotNamespace>
  </transmission>
  <!-- /torso actuators -->
  <!-- LINKS -->
  <!-- shoulder yaw-roll-->
  <link name="arm1_1">
    <inertial>
      <origin xyz="0.0 0.064706 0.0"/>
      <mass value="1.7"/>
      <!-- OK: 1.7 -->
      <inertia ixx="0.002332" ixy="0.0" ixz="0.0" iyy="0.001345" iyz="-0.0" izz="0.002332"/>
    </inertial>
    <visual>
      <origin xyz="0.0 0.05 0.0"/>
      <geometry>
        <box size="0.05 0.1 0.05"/>
        <!-- OK -->
      </geometry>
      <material name="blue"/>
    </visual>
    <visual>
      <origin rpy="1.5707963268 0 0" xyz="0 0.0 0"/>
      <geometry>
        <cylinder length="0.1" radius="0.05"/>
      </geometry>
      <material name="grey"/>
    </visual>
    <!--	<collision>
		<origin xyz="0.0 0.05 0.0"/>
		<geometry>
			<box size="${link_visual} 0.1 ${link_visual}"/> 
		</geometry>
		<material name="blue"/>
	</collision> -->
    <collision>
      <origin rpy="1.5707963268 0 0" xyz="0 0.0 0"/>
      <geometry>
        <cylinder length="0.05" radius="0.05"/>
      </geometry>
      <material name="grey"/>
    </collision>
  </link>
  <!-- shoulder yaw-roll-->
  <!-- shoulder roll-pitch-->
  <link name="arm1_2">
    <inertial>
      <origin xyz="0.0 0.0 -0.125"/>
      <mass value="2.0"/>
      <!-- OK: 2 -->
      <inertia ixx="0.005879" ixy="0.0" ixz="0.0" iyy="0.005879" iyz="0.0" izz="0.001525"/>
    </inertial>
    <visual>
      <origin xyz="0.0 0.0 -0.1"/>
      <geometry>
        <box size="0.05 0.05 0.2"/>
        <!-- OK -->
      </geometry>
      <material name="grey"/>
    </visual>
    <visual>
      <origin rpy="0 1.57 0" xyz="0 0.0 0"/>
      <geometry>
        <cylinder length="0.1" radius="0.05"/>
      </geometry>
    </visual>
    <!--	<collision>
		<origin xyz="0.0 0.0 -0.1"/>
		<geometry>
			<box size="${link_visual} ${link_visual} 0.2"/> 
		</geometry>
		<material name="grey"/>
	</collision> -->
    <collision>
      <origin rpy="0 1.57 0" xyz="0 0.0 0"/>
      <geometry>
        <cylinder length="0.05" radius="0.05"/>
      </geometry>
    </collision>
  </link>
  <!-- shoulder roll-pitch-->
  <!-- shoulder-elbow -->
  <link name="arm1_3">
    <inertial>
      <origin xyz="0.0 0.0 -0.09375"/>
      <mass value="2.0"/>
      <!-- OK: 2 -->
      <inertia ixx="0.003989" ixy="0.0" ixz="0.0" iyy="0.003884" iyz="-0.0" izz="0.001629"/>
      <!-- TODO -->
    </inertial>
    <visual>
      <origin xyz="0.0 0.0 -0.075"/>
      <geometry>
        <box size="0.05 0.05 0.15"/>
        <!-- OK -->
      </geometry>
      <material name="grey"/>
    </visual>
    <visual>
      <origin rpy="0 0 0" xyz="0 0.0 0"/>
      <geometry>
        <cylinder length="0.1" radius="0.05"/>
      </geometry>
    </visual>
    <!--	<collision>
		<origin xyz="0.0 0.0 -0.075"/>
		<geometry>
			<box size="${link_visual} ${link_visual} 0.15"/> 
		</geometry>
		<material name="grey"/>
	</collision> -->
    <collision>
      <origin rpy="0 0 0" xyz="0 0.0 0"/>
      <geometry>
        <cylinder length="0.05" radius="0.05"/>
      </geometry>
    </collision>
  </link>
  <!-- /shoulder-elbow -->
  <!-- elbow yaw-pitch -->
  <link name="arm1_4">
    <inertial>
      <origin xyz="0.0 0.0 -0.09"/>
      <mass value="1.3"/>
      <!-- OK: 1.3 -->
      <inertia ixx="0.002589" ixy="0.0" ixz="0.0" iyy="0.002589" iyz="0.0" izz="0.001105"/>
    </inertial>
    <visual>
      <origin xyz="0 0.0 -0.065"/>
      <geometry>
        <box size="0.05 0.05 0.13"/>
        <!-- OK -->
      </geometry>
      <material name="blue"/>
    </visual>
    <visual>
      <origin rpy="1.57 0 0" xyz="0 0.0 0"/>
      <geometry>
        <cylinder length="0.1" radius="0.05"/>
      </geometry>
      <material name="blue"/>
    </visual>
    <!--	<collision>
		<origin xyz="0 0.0 -0.065"/>
		<geometry> 
			<box size="${link_visual} ${link_visual} 0.13"/> 
		</geometry>
		<material name="blue"/>
	</collision> -->
    <collision>
      <origin rpy="1.57 0 0" xyz="0 0.0 0"/>
      <geometry>
        <cylinder length="0.05" radius="0.05"/>
      </geometry>
      <material name="blue"/>
    </collision>
  </link>
  <!-- /elbow yaw-pitch -->
  <!-- elbow-wrist -->
  <link name="arm1_5">
    <inertial>
      <origin xyz="0.0 0.0 -0.067857"/>
      <mass value="1.4"/>
      <!-- OK: 1.4 -->
      <inertia ixx="0.002073" ixy="0.0" ixz="0.0" iyy="0.001969" iyz="-0.0" izz="0.001269"/>
    </inertial>
    <visual>
      <origin xyz="0.0 0.0 -0.05"/>
      <geometry>
        <box size="0.05 0.05 0.1"/>
        <!-- OK -->
      </geometry>
      <material name="grey"/>
    </visual>
    <visual>
      <origin rpy="0 0 0" xyz="0 0.0 0"/>
      <geometry>
        <cylinder length="0.1" radius="0.05"/>
      </geometry>
    </visual>
    <!--	<collision>
		<origin xyz="0.0 0.0 -0.05"/>
		<geometry>
			<box size="${link_visual} ${link_visual} 0.1"/> 
		</geometry>
		<material name="grey"/>
	</collision> -->
    <collision>
      <origin rpy="0 0 0" xyz="0 0.0 0"/>
      <geometry>
        <cylinder length="0.05" radius="0.05"/>
      </geometry>
    </collision>
  </link>
  <!-- /elbow-wrist -->
  <!-- wrist yaw-pitch -->
  <link name="arm1_6">
    <inertial>
      <origin xyz="0.0 0.0 -0.094545"/>
      <mass value="1.1"/>
      <!-- OK: 1.1 -->
      <inertia ixx="0.002301" ixy="0.0" ixz="0.0" iyy="0.002301" iyz="0.0" izz="0.000985"/>
    </inertial>
    <visual>
      <origin xyz="0 0.0 -0.065"/>
      <geometry>
        <box size="0.05 0.05 0.13"/>
        <!-- OK -->
      </geometry>
      <material name="blue"/>
    </visual>
    <visual>
      <origin rpy="1.57 0 0" xyz="0 0.0 0"/>
      <geometry>
        <cylinder length="0.1" radius="0.05"/>
      </geometry>
      <material name="blue"/>
    </visual>
    <!--	<collision>
		<origin xyz="0 0.0 -0.065"/>
		<geometry>
			<box size="${link_visual} ${link_visual} 0.13"/> 
		</geometry>
		<material name="blue"/>
	</collision> -->
    <collision>
      <origin rpy="1.57 0 0" xyz="0 0.0 0"/>
      <geometry>
        <cylinder length="0.05" radius="0.05"/>
      </geometry>
      <material name="blue"/>
    </collision>
  </link>
  <!-- /wrist yaw-pitch -->
  <!-- hand -->
  <link name="arm1_7">
    <inertial>
      <origin xyz="0.0 0.0 -0.075"/>
      <mass value="1.7"/>
      <!-- OK: 1.7 -->
      <inertia ixx="0.001303" ixy="0.0" ixz="0.0" iyy="0.001303" iyz="0.0" izz="0.00102"/>
    </inertial>
    <visual>
      <origin xyz="0.0 0.0 -0.075"/>
      <geometry>
        <box size="0.05 0.05 0.15"/>
        <!-- OK -->
      </geometry>
      <material name="grey"/>
    </visual>
    <visual>
      <origin rpy="0 0 0" xyz="0 0.0 0"/>
      <geometry>
        <cylinder length="0.1" radius="0.05"/>
      </geometry>
    </visual>
    <!--	<collision>
		<origin xyz="0.0 0.0 -0.075"/>
		<geometry>
			<box size="${link_visual} ${link_visual} 0.15"/> 
		</geometry>
		<material name="grey"/>
	</collision> -->
    <collision>
      <origin rpy="0 0 0" xyz="0 0.0 0"/>
      <geometry>
        <cylinder length="0.05" radius="0.05"/>
      </geometry>
    </collision>
  </link>
  <!--	<link name="mass${arm_num}_body">
	<inertial>
		<origin xyz="0 0 0"/> -->
  <!--		<mass value="10"/> -->
  <!-- OK: 1.7 -->
  <!--		<inertia ixx="0.001" ixy="0.00" ixz="0.00" iyy="0.001" iyz="0.00" izz="0.001"/> 
	</inertial>
	
	<visual>
		<origin xyz="0.0 0.0 0"/>
		<geometry>
			<box size="0.10 0.10 0.10"/>-->
  <!-- OK -->
  <!--		</geometry>
		<material name="red"/>
	</visual>

	</link> -->
  <!-- /hand -->
  <!-- /LINKS -->
  <!-- JOINTS -->
  <!-- shoulder yaw -->
  <joint name="j_arm1_1" type="revolute">
    <parent link="torso_2"/>
    <child link="arm1_1"/>
    <origin rpy="0.0 0 -0.5236026689864071" xyz="0.04576 0.169137 0.190626"/>
    <axis xyz="0 0.984807753012 0.173648177667"/>
    <limit effort="350" lower="-3.665" upper="1.920" velocity="6.5"/>
    <!-- TODO -->
  </joint>
  <!-- /shoulder yaw -->
  <!-- shoulder roll -->
  <joint name="j_arm1_2" type="revolute">
    <parent link="arm1_1"/>
    <child link="arm1_2"/>
    <origin xyz="-0.09115 0.06106 0.010766"/>
    <axis xyz="-1 0 0"/>
    <limit effort="350" lower="-3.49" upper="0" velocity="6.5"/>
    <!-- TODO -->
  </joint>
  <!-- /shoulder roll -->
  <!-- shoulder pitch-->
  <joint name="j_arm1_3" type="revolute">
    <parent link="arm1_2"/>
    <child link="arm1_3"/>
    <origin xyz="0.09115 0 -0.21915"/>
    <axis xyz="0 0 -1"/>
    <limit effort="350" lower="-2.618" upper="2.618" velocity="6.5"/>
    <!-- TODO -->
  </joint>
  <!-- /shoulder pitch -->
  <!-- elbow yaw -->
  <joint name="j_arm1_4" type="revolute">
    <parent link="arm1_3"/>
    <child link="arm1_4"/>
    <origin xyz="0.040 0.05615 -0.074"/>
    <axis xyz="0 1 0"/>
    <limit effort="350" lower="-2.530" upper="0.349" velocity="6.5"/>
    <!-- TODO -->
  </joint>
  <!-- /elbow yaw -->
  <!-- elbow pitch-->
  <joint name="j_arm1_5" type="revolute">
    <parent link="arm1_4"/>
    <child link="arm1_5"/>
    <origin xyz="-0.015 -0.05615 -0.061"/>
    <axis xyz="0 0 1"/>
    <limit effort="350" lower="-2.618" upper="2.618" velocity="6.5"/>
    <!-- TODO -->
  </joint>
  <!-- /elbow pitch-->
  <!-- wrist yaw-->
  <joint name="j_arm1_6" type="revolute">
    <parent link="arm1_5"/>
    <child link="arm1_6"/>
    <origin xyz="0 0.049 -0.180"/>
    <axis xyz="0 1 0"/>
    <limit effort="350" lower="-1.570" upper="1.570" velocity="6.5"/>
    <!-- TODO -->
  </joint>
  <!-- /wrist yaw-->
  <!-- wrist pitch-->
  <joint name="j_arm1_7" type="revolute">
    <parent link="arm1_6"/>
    <child link="arm1_7"/>
    <origin xyz="0 -0.049 -0.169"/>
    <axis xyz="0 0 -1"/>
    <limit effort="350" lower="-2.618" upper="2.618" velocity="6.5"/>
    <!-- TODO -->
  </joint>
  <!--	<joint name="mass${arm_num}" type="fixed">
		<parent link="arm${arm_num}_7"/>
		<child link="mass${arm_num}_body"/>
		<origin xyz="0 0 -0.15"/> 
	</joint> -->
  <!-- /wrist pitch-->
  <transmission name="t_j_arm1_1">
    <type> transmission_interface/SimpleTransmission</type>
    <joint name="j_arm1_1">
      <hardwareInterface>EffortJointInterface</hardwareInterface>
    </joint>
    <actuator name="motor_j_arm1_1">
      <hardwareInterface>EffortJointInterface</hardwareInterface>
      <machanicalReduction>1</machanicalReduction>
    </actuator>
    <robotNamespace>/centauro</robotNamespace>
  </transmission>
  <transmission name="t_j_arm1_2">
    <type> transmission_interface/SimpleTransmission</type>
    <joint name="j_arm1_2">
      <hardwareInterface>EffortJointInterface</hardwareInterface>
    </joint>
    <actuator name="motor_j_arm1_2">
      <hardwareInterface>EffortJointInterface</hardwareInterface>
      <machanicalReduction>1</machanicalReduction>
    </actuator>
    <robotNamespace>/centauro</robotNamespace>
  </transmission>
  <transmission name="t_j_arm1_3">
    <type> transmission_interface/SimpleTransmission</type>
    <joint name="j_arm1_3">
      <hardwareInterface>EffortJointInterface</hardwareInterface>
    </joint>
    <actuator name="motor_j_arm1_3">
      <hardwareInterface>EffortJointInterface</hardwareInterface>
      <machanicalReduction>1</machanicalReduction>
    </actuator>
    <robotNamespace>/centauro</robotNamespace>
  </transmission>
  <transmission name="t_j_arm1_4">
    <type> transmission_interface/SimpleTransmission</type>
    <joint name="j_arm1_4">
      <hardwareInterface>EffortJointInterface</hardwareInterface>
    </joint>
    <actuator name="motor_j_arm1_4">
      <hardwareInterface>EffortJointInterface</hardwareInterface>
      <machanicalReduction>1</machanicalReduction>
    </actuator>
    <robotNamespace>/centauro</robotNamespace>
  </transmission>
  <transmission name="t_j_arm1_5">
    <type> transmission_interface/SimpleTransmission</type>
    <joint name="j_arm1_5">
      <hardwareInterface>EffortJointInterface</hardwareInterface>
    </joint>
    <actuator name="motor_j_arm1_5">
      <hardwareInterface>EffortJointInterface</hardwareInterface>
      <machanicalReduction>1</machanicalReduction>
    </actuator>
    <robotNamespace>/centauro</robotNamespace>
  </transmission>
  <transmission name="t_j_arm1_6">
    <type> transmission_interface/SimpleTransmission</type>
    <joint name="j_arm1_6">
      <hardwareInterface>EffortJointInterface</hardwareInterface>
    </joint>
    <actuator name="motor_j_arm1_6">
      <hardwareInterface>EffortJointInterface</hardwareInterface>
      <machanicalReduction>1</machanicalReduction>
    </actuator>
    <robotNamespace>/centauro</robotNamespace>
  </transmission>
  <transmission name="t_j_arm1_7">
    <type> transmission_interface/SimpleTransmission</type>
    <joint name="j_arm1_7">
      <hardwareInterface>EffortJointInterface</hardwareInterface>
    </joint>
    <actuator name="motor_j_arm1_7">
      <hardwareInterface>EffortJointInterface</hardwareInterface>
      <machanicalReduction>1</machanicalReduction>
    </actuator>
    <robotNamespace>/centauro</robotNamespace>
  </transmission>
  <!-- /actuators -->
  <!-- LINKS -->
  <!-- shoulder yaw-roll-->
  <link name="arm2_1">
    <inertial>
      <origin xyz="0.0 -0.064706 0.0"/>
      <mass value="1.7"/>
      <!-- OK: 1.7 -->
      <inertia ixx="0.002332" ixy="0.0" ixz="0.0" iyy="0.001345" iyz="-0.0" izz="0.002332"/>
    </inertial>
    <visual>
      <origin xyz="0.0 -0.05 0.0"/>
      <geometry>
        <box size="0.05 0.1 0.05"/>
        <!-- OK -->
      </geometry>
      <material name="blue"/>
    </visual>
    <visual>
      <origin rpy="1.5707963268 0 0" xyz="0 0.0 0"/>
      <geometry>
        <cylinder length="0.1" radius="0.05"/>
      </geometry>
      <material name="grey"/>
    </visual>
    <!--	<collision>
		<origin xyz="0.0 0.05 0.0"/>
		<geometry>
			<box size="${link_visual} 0.1 ${link_visual}"/> 
		</geometry>
		<material name="blue"/>
	</collision> -->
    <collision>
      <origin rpy="1.5707963268 0 0" xyz="0 0.0 0"/>
      <geometry>
        <cylinder length="0.05" radius="0.05"/>
      </geometry>
      <material name="grey"/>
    </collision>
  </link>
  <!-- shoulder yaw-roll-->
  <!-- shoulder roll-pitch-->
  <link name="arm2_2">
    <inertial>
      <origin xyz="0.0 -0.0 -0.125"/>
      <mass value="2.0"/>
      <!-- OK: 2 -->
      <inertia ixx="0.005879" ixy="0.0" ixz="0.0" iyy="0.005879" iyz="0.0" izz="0.001525"/>
    </inertial>
    <visual>
      <origin xyz="0.0 0.0 -0.1"/>
      <geometry>
        <box size="0.05 0.05 0.2"/>
        <!-- OK -->
      </geometry>
      <material name="grey"/>
    </visual>
    <visual>
      <origin rpy="0 1.57 0" xyz="0 0.0 0"/>
      <geometry>
        <cylinder length="0.1" radius="0.05"/>
      </geometry>
    </visual>
    <!--	<collision>
		<origin xyz="0.0 0.0 -0.1"/>
		<geometry>
			<box size="${link_visual} ${link_visual} 0.2"/> 
		</geometry>
		<material name="grey"/>
	</collision> -->
    <collision>
      <origin rpy="0 1.57 0" xyz="0 0.0 0"/>
      <geometry>
        <cylinder length="0.05" radius="0.05"/>
      </geometry>
    </collision>
  </link>
  <!-- shoulder roll-pitch-->
  <!-- shoulder-elbow -->
  <link name="arm2_3">
    <inertial>
      <origin xyz="0.0 -0.0 -0.09375"/>
      <mass value="2.0"/>
      <!-- OK: 2 -->
      <inertia ixx="0.003989" ixy="0.0" ixz="0.0" iyy="0.003884" iyz="-0.0" izz="0.001629"/>
      <!-- TODO -->
    </inertial>
    <visual>
      <origin xyz="0.0 0.0 -0.075"/>
      <geometry>
        <box size="0.05 0.05 0.15"/>
        <!-- OK -->
      </geometry>
      <material name="grey"/>
    </visual>
    <visual>
      <origin rpy="0 0 0" xyz="0 0.0 0"/>
      <geometry>
        <cylinder length="0.1" radius="0.05"/>
      </geometry>
    </visual>
    <!--	<collision>
		<origin xyz="0.0 0.0 -0.075"/>
		<geometry>
			<box size="${link_visual} ${link_visual} 0.15"/> 
		</geometry>
		<material name="grey"/>
	</collision> -->
    <collision>
      <origin rpy="0 0 0" xyz="0 0.0 0"/>
      <geometry>
        <cylinder length="0.05" radius="0.05"/>
      </geometry>
    </collision>
  </link>
  <!-- /shoulder-elbow -->
  <!-- elbow yaw-pitch -->
  <link name="arm2_4">
    <inertial>
      <origin xyz="0.0 -0.0 -0.09"/>
      <mass value="1.3"/>
      <!-- OK: 1.3 -->
      <inertia ixx="0.002589" ixy="0.0" ixz="0.0" iyy="0.002589" iyz="0.0" izz="0.001105"/>
    </inertial>
    <visual>
      <origin xyz="0 0.0 -0.065"/>
      <geometry>
        <box size="0.05 -0.05 0.13"/>
        <!-- OK -->
      </geometry>
      <material name="blue"/>
    </visual>
    <visual>
      <origin rpy="1.57 0 0" xyz="0 0.0 0"/>
      <geometry>
        <cylinder length="0.1" radius="0.05"/>
      </geometry>
      <material name="blue"/>
    </visual>
    <!--	<collision>
		<origin xyz="0 0.0 -0.065"/>
		<geometry> 
			<box size="${link_visual} ${link_visual} 0.13"/> 
		</geometry>
		<material name="blue"/>
	</collision> -->
    <collision>
      <origin rpy="1.57 0 0" xyz="0 0.0 0"/>
      <geometry>
        <cylinder length="0.05" radius="0.05"/>
      </geometry>
      <material name="blue"/>
    </collision>
  </link>
  <!-- /elbow yaw-pitch -->
  <!-- elbow-wrist -->
  <link name="arm2_5">
    <inertial>
      <origin xyz="0.0 0.0 -0.067857"/>
      <mass value="1.4"/>
      <!-- OK: 1.4 -->
      <inertia ixx="0.002073" ixy="0.0" ixz="0.0" iyy="0.001969" iyz="-0.0" izz="0.001269"/>
    </inertial>
    <visual>
      <origin xyz="0.0 0.0 -0.05"/>
      <geometry>
        <box size="0.05 0.05 0.1"/>
        <!-- OK -->
      </geometry>
      <material name="grey"/>
    </visual>
    <visual>
      <origin rpy="0 0 0" xyz="0 0.0 0"/>
      <geometry>
        <cylinder length="0.1" radius="0.05"/>
      </geometry>
    </visual>
    <!--	<collision>
		<origin xyz="0.0 0.0 -0.05"/>
		<geometry>
			<box size="${link_visual} ${link_visual} 0.1"/> 
		</geometry>
		<material name="grey"/>
	</collision> -->
    <collision>
      <origin rpy="0 0 0" xyz="0 0.0 0"/>
      <geometry>
        <cylinder length="0.05" radius="0.05"/>
      </geometry>
    </collision>
  </link>
  <!-- /elbow-wrist -->
  <!-- wrist yaw-pitch -->
  <link name="arm2_6">
    <inertial>
      <origin xyz="0.0 0.0 -0.094545"/>
      <mass value="1.1"/>
      <!-- OK: 1.1 -->
      <inertia ixx="0.002301" ixy="0.0" ixz="0.0" iyy="0.002301" iyz="0.0" izz="0.000985"/>
    </inertial>
    <visual>
      <origin xyz="0 0.0 -0.065"/>
      <geometry>
        <box size="0.05 0.05 0.13"/>
        <!-- OK -->
      </geometry>
      <material name="blue"/>
    </visual>
    <visual>
      <origin rpy="1.57 0 0" xyz="0 0.0 0"/>
      <geometry>
        <cylinder length="0.1" radius="0.05"/>
      </geometry>
      <material name="blue"/>
    </visual>
    <!--	<collision>
		<origin xyz="0 0.0 -0.065"/>
		<geometry>
			<box size="${link_visual} ${link_visual} 0.13"/> 
		</geometry>
		<material name="blue"/>
	</collision> -->
    <collision>
      <origin rpy="1.57 0 0" xyz="0 0.0 0"/>
      <geometry>
        <cylinder length="0.05" radius="0.05"/>
      </geometry>
      <material name="blue"/>
    </collision>
  </link>
  <!-- /wrist yaw-pitch -->
  <!-- hand -->
  <link name="arm2_7">
    <inertial>
      <origin xyz="0.0 0.0 -0.075"/>
      <mass value="1.7"/>
      <!-- OK: 1.7 -->
      <inertia ixx="0.001303" ixy="0.0" ixz="0.0" iyy="0.001303" iyz="0.0" izz="0.00102"/>
    </inertial>
    <visual>
      <origin xyz="0.0 0.0 -0.075"/>
      <geometry>
        <box size="0.05 0.05 0.15"/>
        <!-- OK -->
      </geometry>
      <material name="grey"/>
    </visual>
    <visual>
      <origin rpy="0 0 0" xyz="0 0.0 0"/>
      <geometry>
        <cylinder length="0.1" radius="0.05"/>
      </geometry>
    </visual>
    <!--	<collision>
		<origin xyz="0.0 0.0 -0.075"/>
		<geometry>
			<box size="${link_visual} ${link_visual} 0.15"/> 
		</geometry>
		<material name="grey"/>
	</collision> -->
    <collision>
      <origin rpy="0 0 0" xyz="0 0.0 0"/>
      <geometry>
        <cylinder length="0.05" radius="0.05"/>
      </geometry>
    </collision>
  </link>
  <!--	<link name="mass${arm_num}_body">
	<inertial>
		<origin xyz="0 0 0"/> -->
  <!--		<mass value="10"/> -->
  <!-- OK: 1.7 -->
  <!--		<inertia ixx="0.001" ixy="0.00" ixz="0.00" iyy="0.001" iyz="0.00" izz="0.001"/> 
	</inertial>
	
	<visual>
		<origin xyz="0.0 0.0 0"/>
		<geometry>
			<box size="0.10 0.10 0.10"/>-->
  <!-- OK -->
  <!--		</geometry>
		<material name="red"/>
	</visual>

	</link> -->
  <!-- /hand -->
  <!-- /LINKS -->
  <!-- JOINTS -->
  <!-- shoulder yaw -->
  <joint name="j_arm2_1" type="revolute">
    <parent link="torso_2"/>
    <child link="arm2_1"/>
    <origin rpy="0.0 0 0.5236026689864071" xyz="0.0457475 -0.169137 0.190626"/>
    <axis xyz="0 -0.984807753012 0.173648177667"/>
    <limit effort="350" lower="-1.920" upper="3.665" velocity="6.5"/>
  </joint>
  <!-- /shoulder yaw -->
  <!-- shoulder roll -->
  <joint name="j_arm2_2" type="revolute">
    <parent link="arm2_1"/>
    <child link="arm2_2"/>
    <origin xyz="-0.09115 -0.06106 0.010766"/>
    <axis xyz="-1 0 0"/>
    <limit effort="350" lower="0" upper="3.49" velocity="6.5"/>
    <!-- TODO -->
  </joint>
  <!-- /shoulder roll -->
  <!-- shoulder pitch-->
  <joint name="j_arm2_3" type="revolute">
    <parent link="arm2_2"/>
    <child link="arm2_3"/>
    <origin xyz="0.09115 0 -0.21915"/>
    <axis xyz="0 0 -1"/>
    <limit effort="350" lower="-2.618" upper="2.618" velocity="6.5"/>
    <!-- TODO -->
  </joint>
  <!-- /shoulder pitch -->
  <!-- elbow yaw -->
  <joint name="j_arm2_4" type="revolute">
    <parent link="arm2_3"/>
    <child link="arm2_4"/>
    <origin xyz="0.040 -0.05615 -0.074"/>
    <axis xyz="0 -1 0"/>
    <limit effort="350" lower="-0.349" upper="2.530" velocity="6.5"/>
    <!-- TODO -->
  </joint>
  <!-- /elbow yaw -->
  <!-- elbow pitch-->
  <joint name="j_arm2_5" type="revolute">
    <parent link="arm2_4"/>
    <child link="arm2_5"/>
    <origin xyz="-0.015 0.05615 -0.061"/>
    <axis xyz="0 0 1"/>
    <limit effort="350" lower="-2.618" upper="2.618" velocity="6.5"/>
    <!-- TODO -->
  </joint>
  <!-- /elbow pitch-->
  <!-- wrist yaw-->
  <joint name="j_arm2_6" type="revolute">
    <parent link="arm2_5"/>
    <child link="arm2_6"/>
    <origin xyz="0 -0.049 -0.180"/>
    <axis xyz="0 -1 0"/>
    <limit effort="350" lower="-1.570" upper="1.570" velocity="6.5"/>
    <!-- TODO -->
  </joint>
  <!-- /wrist yaw-->
  <!-- wrist pitch-->
  <joint name="j_arm2_7" type="revolute">
    <parent link="arm2_6"/>
    <child link="arm2_7"/>
    <origin xyz="0 0.049 -0.169"/>
    <axis xyz="0 0 -1"/>
    <limit effort="350" lower="-2.618" upper="2.618" velocity="6.5"/>
    <!-- TODO -->
  </joint>
  <!--	<joint name="mass${arm_num}" type="fixed">
		<parent link="arm${arm_num}_7"/>
		<child link="mass${arm_num}_body"/>
		<origin xyz="0 0 -0.15"/> 
	</joint> -->
  <!-- /wrist pitch-->
  <transmission name="t_j_arm2_1">
    <type> transmission_interface/SimpleTransmission</type>
    <joint name="j_arm2_1">
      <hardwareInterface>EffortJointInterface</hardwareInterface>
    </joint>
    <actuator name="motor_j_arm2_1">
      <hardwareInterface>EffortJointInterface</hardwareInterface>
      <machanicalReduction>1</machanicalReduction>
    </actuator>
    <robotNamespace>/centauro</robotNamespace>
  </transmission>
  <transmission name="t_j_arm2_2">
    <type> transmission_interface/SimpleTransmission</type>
    <joint name="j_arm2_2">
      <hardwareInterface>EffortJointInterface</hardwareInterface>
    </joint>
    <actuator name="motor_j_arm2_2">
      <hardwareInterface>EffortJointInterface</hardwareInterface>
      <machanicalReduction>1</machanicalReduction>
    </actuator>
    <robotNamespace>/centauro</robotNamespace>
  </transmission>
  <transmission name="t_j_arm2_3">
    <type> transmission_interface/SimpleTransmission</type>
    <joint name="j_arm2_3">
      <hardwareInterface>EffortJointInterface</hardwareInterface>
    </joint>
    <actuator name="motor_j_arm2_3">
      <hardwareInterface>EffortJointInterface</hardwareInterface>
      <machanicalReduction>1</machanicalReduction>
    </actuator>
    <robotNamespace>/centauro</robotNamespace>
  </transmission>
  <transmission name="t_j_arm2_4">
    <type> transmission_interface/SimpleTransmission</type>
    <joint name="j_arm2_4">
      <hardwareInterface>EffortJointInterface</hardwareInterface>
    </joint>
    <actuator name="motor_j_arm2_4">
      <hardwareInterface>EffortJointInterface</hardwareInterface>
      <machanicalReduction>1</machanicalReduction>
    </actuator>
    <robotNamespace>/centauro</robotNamespace>
  </transmission>
  <transmission name="t_j_arm2_5">
    <type> transmission_interface/SimpleTransmission</type>
    <joint name="j_arm2_5">
      <hardwareInterface>EffortJointInterface</hardwareInterface>
    </joint>
    <actuator name="motor_j_arm2_5">
      <hardwareInterface>EffortJointInterface</hardwareInterface>
      <machanicalReduction>1</machanicalReduction>
    </actuator>
    <robotNamespace>/centauro</robotNamespace>
  </transmission>
  <transmission name="t_j_arm2_6">
    <type> transmission_interface/SimpleTransmission</type>
    <joint name="j_arm2_6">
      <hardwareInterface>EffortJointInterface</hardwareInterface>
    </joint>
    <actuator name="motor_j_arm2_6">
      <hardwareInterface>EffortJointInterface</hardwareInterface>
      <machanicalReduction>1</machanicalReduction>
    </actuator>
    <robotNamespace>/centauro</robotNamespace>
  </transmission>
  <transmission name="t_j_arm2_7">
    <type> transmission_interface/SimpleTransmission</type>
    <joint name="j_arm2_7">
      <hardwareInterface>EffortJointInterface</hardwareInterface>
    </joint>
    <actuator name="motor_j_arm2_7">
      <hardwareInterface>EffortJointInterface</hardwareInterface>
      <machanicalReduction>1</machanicalReduction>
    </actuator>
    <robotNamespace>/centauro</robotNamespace>
  </transmission>
  <!-- /actuators -->
  <!-- /arms -->
  <!-- /torso -->
  <!-- /legs -->
</robot>

