<?xml version="1.0" ?>
<robot name="kuka-lwr" xmlns:xacro="http://www.ros.org/wiki/xacro">
    <!-- inertial parameter from Claudio Gaz, 2016: Extracting Feasible Robot Parameters from Dynamic Coefficients using Nonlinear Optimization Methods -->
    <material name="DarkGrey">
        <color rgba="0.3 0.3 0.3 1.0" />
    </material>
    <material name="Red">
        <color rgba="0.3 0.3 0.3 1.0" />
    </material>
    <material name="Black">
        <color rgba="0 0 0 1.0" />
    </material>
    <material name="Orange">
        <color rgba="1.0 0.487 0 1.0" />
    </material>
    <material name="Silver">
        <color rgba="1.0 1.0 1.0 1.0" />
    </material>
    <material name="Grey">
        <color rgba="0.7 0.7 0.7 1.0" />
    </material>
    <material name="Blue">
        <color rgba="0.0 0.0 0.8 1.0" />
    </material>
    <material name="HandGray">
        <color rgba="0.953 0.996 0.694 1.0" />
    </material>
    <material name="SickBlue">
        <color rgba="0.3058 0.5921 0.7294 1.0" />
    </material>
    <link name="world" />
    <joint name="arm_world_joint" type="fixed">
        <origin rpy="0 0 0" xyz="0 0 0.01" />
        <parent link="world" />
        <child link="lwr_base_link" />
    </joint>
    <!--link name="world_link">
    <inertial>
      <mass value="50.0"/>
      <com xyz="0 0 0"/>
      <inertia ixx="0.01" ixy="0.00" ixz="0.00" iyy="0.01" iyz="0.00" izz="0.01"/>
    </inertial>
    <visual>
      <origin rpy="0 0 0" xyz="0 0 0.95"/>
      <geometry>
        <box size="0.5 0.5 0.05"/>
      </geometry>
    </visual>
    <collision>
      <origin rpy="0 0 0" xyz="0 0 0.50"/>
      <geometry>
        <box size="0.5 0.5 0.05"/>
      </geometry>
    </collision>
  </link-->
    <!-- First (shoulder) element of the arm. Fixed to its parent. -->
    <!--joint name="world_lwr_base_joint" type="fixed">
    <origin rpy="0 0 0" xyz="0 0 1.1"/>
    <parent link="world_link"/>
    <child link="lwr_base_link"/>
  </joint-->
    <link name="lwr_base_link">
        <inertial>
            <mass value="1.2" />
            <origin rpy="0 0 0" xyz="0 0 0.055" />
            <inertia ixx="0.00229" ixy="0" ixz="0" iyy="0.00216" iyz="0" izz="0.00229" />
        </inertial>
        <visual>
            <origin rpy="0 0 0" xyz="0 0 0" />
            <geometry>
                <mesh filename="package://lwr_description/meshes/kuka/base.STL" />
            </geometry>
            <material name="Orange" />
        </visual>
        <collision>
            <origin rpy="0 0 0" xyz="0 0 0.01" />
            <geometry>
                <mesh filename="model://kuka-lwr-4plus/meshes/convex/arm_base_convex.stl" scale="0.9 0.9 0.9" />
            </geometry>
        </collision>
    </link>
    <gazebo reference="lwr_base_link">
        <!--<material value="kuka-lwr.material"/>-->
    </gazebo>
    <joint name="lwr_0_joint" type="revolute">
        <origin rpy="0 0 0" xyz="0 0 0.11" />
        <axis xyz="0 0 1" />
        <limit effort="176" lower="-2.96705972839" upper="2.96705972839" velocity="1.91986217719" />
        <safety_controller k_position="100" k_velocity="2" soft_lower_limit="-2.93215314335" soft_upper_limit="2.93215314335" />
        <dynamics damping="0.0" />
        <parent link="lwr_base_link" />
        <child link="lwr_1_link" />
    </joint>
    <gazebo reference="lwr_0_joint">
        <provideFeedback>1</provideFeedback>
        <implicitSpringDamper>1</implicitSpringDamper>
    </gazebo>
    <transmission name="lwr_0_trans" type="SimpleTransmission">
        <actuator name="lwr_0_motor" />
        <joint name="lwr_0_joint" />
        <mechanicalReduction>1.0</mechanicalReduction>
    </transmission>
    <link name="lwr_1_link">
        <inertial>
            <mass value="4.1948152162" />
            <origin rpy="0 0 0" xyz="-0.0216387515 0.01 -0.0376881829" />
            <inertia ixx="0.01" ixy="0.01" ixz="0.01" iyy="0.0018932828" iyz="0.01" izz="0.01" />
        </inertial>
        <visual>
            <origin rpy="0 0 3.14159265359" xyz="0 0 0" />
            <geometry>
                <mesh filename="package://lwr_description/meshes/kuka/link_1.STL" />
            </geometry>
            <material name="Orange" />
        </visual>
        <collision>
            <origin rpy="0 0 3.14159265359" xyz="0 0 0" />
            <geometry>
                <mesh filename="model://kuka-lwr-4plus/meshes/convex/arm_segment_a_convex.stl" scale="1.0 1.0 1.0" />
            </geometry>
        </collision>
    </link>
    <gazebo reference="lwr_1_link">
        <!--<material value="kuka-lwr.material"/>-->
    </gazebo>
    <joint name="lwr_1_joint" type="revolute">
        <origin rpy="0 0 0" xyz="0 0 0.20" />
        <axis xyz="0 -1 0" />
        <limit effort="176" lower="-2.09439510239" upper="2.09439510239" velocity="1.91986217719" />
        <safety_controller k_position="100" k_velocity="2" soft_lower_limit="-2.05948851735" soft_upper_limit="2.05948851735" />
        <dynamics damping="0.0" />
        <parent link="lwr_1_link" />
        <child link="lwr_2_link" />
    </joint>
    <gazebo reference="lwr_1_joint">
        <provideFeedback>1</provideFeedback>
        <implicitSpringDamper>1</implicitSpringDamper>
    </gazebo>
    <transmission name="lwr_1_trans" type="pr2_mechanism_model/SimpleTransmission">
        <actuator name="lwr_1_motor" />
        <joint name="lwr_1_joint" />
        <mechanicalReduction>1.0</mechanicalReduction>
    </transmission>
    <link name="lwr_2_link">
        <inertial>
            <mass value="4.2996847737" />
            <origin rpy="0 0 0" xyz="0.0003284751 -0.0041132249 0.0823647642" />
            <inertia ixx="0.0474108647" ixy="-0.00000621" ixz="0.0001166457" iyy="0.05" iyz="-0.0009141575" izz="0.001601901" />
        </inertial>
        <visual>
            <origin rpy="3.14159265359 0 3.14159265359" xyz="0 0 0.2" />
            <geometry>
                <mesh filename="package://lwr_description/meshes/kuka/link_2.STL" />
            </geometry>
            <material name="Orange" />
        </visual>
        <collision>
            <origin rpy="3.14159265359 0 3.14159265359" xyz="0 0 0.2" />
            <geometry>
                <mesh filename="model://kuka-lwr-4plus/meshes/convex/arm_segment_b_convex.stl" scale="1.0 1.0 1.0" />
            </geometry>
        </collision>
    </link>
    <gazebo reference="lwr_2_link">
        <!--<material value="kuka-lwr.material"/>-->
    </gazebo>
    <joint name="lwr_2_joint" type="revolute">
        <origin rpy="0 0 0" xyz="0 0 0.20" />
        <axis xyz="0 0 1" />
        <limit effort="100" lower="-2.96705972839" upper="2.96705972839" velocity="2.26892802759" />
        <safety_controller k_position="100" k_velocity="2" soft_lower_limit="-2.93215314335" soft_upper_limit="2.93215314335" />
        <dynamics damping="0.0" />
        <parent link="lwr_2_link" />
        <child link="lwr_3_link" />
    </joint>
    <gazebo reference="lwr_2_joint">
        <provideFeedback>1</provideFeedback>
        <implicitSpringDamper>1</implicitSpringDamper>
    </gazebo>
    <transmission name="lwr_2_trans" type="SimpleTransmission">
        <actuator name="lwr_2_motor" />
        <joint name="lwr_2_joint" />
        <mechanicalReduction>1.0</mechanicalReduction>
    </transmission>
    <link name="lwr_3_link">
        <inertial>
            <mass value="3.658530333" />
            <origin rpy="0 0 0" xyz="0.0002593328 0.1137431845 -0.000100257" />
            <inertia ixx="0.0469510749" ixy="-0.000271431" ixz="4.09E-008" iyy="0.0008344566" iyz="-0.000577228" izz="0.05" />
        </inertial>
        <visual>
            <origin rpy="0 0 0" xyz="0 0 0" />
            <geometry>
                <mesh filename="package://lwr_description/meshes/kuka/link_3.STL" />
            </geometry>
            <material name="Orange" />
        </visual>
        <collision>
            <origin rpy="0 0 0" xyz="0 0 0" />
            <geometry>
                <mesh filename="model://kuka-lwr-4plus/meshes/convex/arm_segment_a_convex.stl" scale="1.0 1.0 1.0" />
            </geometry>
        </collision>
    </link>
    <gazebo reference="lwr_3_link">
        <!--<material value="kuka-lwr.material"/>-->
    </gazebo>
    <joint name="lwr_3_joint" type="revolute">
        <origin rpy="0 0 0" xyz="0 0 0.20" />
        <axis xyz="0 1 0" />
        <limit effort="100" lower="-2.09439510239" upper="2.09439510239" velocity="2.26892802759" />
        <safety_controller k_position="100" k_velocity="2" soft_lower_limit="-2.05948851735" soft_upper_limit="2.05948851735" />
        <dynamics damping="0.0" />
        <parent link="lwr_3_link" />
        <child link="lwr_4_link" />
    </joint>
    <gazebo reference="lwr_3_joint">
        <provideFeedback>1</provideFeedback>
        <implicitSpringDamper>1</implicitSpringDamper>
    </gazebo>
    <transmission name="lwr_3_trans" type="SimpleTransmission">
        <actuator name="lwr_3_motor" />
        <joint name="lwr_3_joint" />
        <mechanicalReduction>1.0</mechanicalReduction>
    </transmission>
    <link name="lwr_4_link">
        <inertial>
            <mass value="2.3846673548" />
            <origin rpy="0 0 0" xyz="-0.0014648843 -0.0000461 0.148580959" />
            <inertia ixx="0.0124233226" ixy="0.000000225" ixz="-0.0005187982" iyy="0.0072708907" iyz="-0.0005484476" izz="0.0099884782" />
        </inertial>
        <visual>
            <origin rpy="0 3.14159265359 3.14159265359" xyz="0 0 0.2" />
            <geometry>
                <mesh filename="package://lwr_description/meshes/kuka/link_4.STL" />
            </geometry>
            <material name="Orange" />
        </visual>
        <collision>
            <origin rpy="0 3.14159265359 3.14159265359" xyz="0 0 0.2" />
            <geometry>
                <mesh filename="model://kuka-lwr-4plus/meshes/convex/arm_segment_b_convex.stl" scale="1.0 1.0 1.0" />
            </geometry>
        </collision>
    </link>
    <gazebo reference="lwr_4_link">
        <!--<material value="kuka-lwr.material"/>-->
    </gazebo>
    <joint name="lwr_4_joint" type="revolute">
        <origin rpy="0 0 0" xyz="0 0 0.20" />
        <axis xyz="0 0 1" />
        <limit effort="100" lower="-2.96705972839" upper="2.96705972839" velocity="2.26892802759" />
        <safety_controller k_position="100" k_velocity="2" soft_lower_limit="-2.93215314335" soft_upper_limit="2.93215314335" />
        <dynamics damping="0.0" />
        <parent link="lwr_4_link" />
        <child link="lwr_5_link" />
    </joint>
    <gazebo reference="lwr_4_joint">
        <provideFeedback>1</provideFeedback>
        <implicitSpringDamper>1</implicitSpringDamper>
    </gazebo>
    <transmission name="lwr_4_trans" type="SimpleTransmission">
        <actuator name="lwr_4_motor" />
        <joint name="lwr_4_joint" />
        <mechanicalReduction>1.0</mechanicalReduction>
    </transmission>
    <link name="lwr_5_link">
        <inertial>
            <mass value="1.7035567183" />
            <origin rpy="0 0 0" xyz="-0.0003791484 -0.0553526131 -0.0101255137" />
            <inertia ixx="0.006322648" ixy="-0.0002163196" ixz="0.00000652" iyy="0.0012020203" iyz="-0.005" izz="0.0070806218" />
        </inertial>
        <visual>
            <origin rpy="0 0 3.14159265359" xyz="0 0 0" />
            <geometry name="lwr_5_geom">
                <mesh filename="package://lwr_description/meshes/kuka/link_5.STL" />
            </geometry>
            <material name="Orange" />
        </visual>
        <collision>
            <origin rpy="0 0 3.14159265359" xyz="0 0 0" />
            <geometry>
                <mesh filename="model://kuka-lwr-4plus/meshes/convex/arm_segment_last_convex.stl" scale="1.0 1.0 1.0" />
            </geometry>
        </collision>
    </link>
    <gazebo reference="lwr_5_link">
        <!--<material value="kuka-lwr.material"/>-->
    </gazebo>
    <joint name="lwr_5_joint" type="revolute">
        <origin rpy="0 0 0" xyz="0 0 0.19" />
        <axis xyz="0 -1 0" />
        <limit effort="38" lower="-2.09439510239" upper="2.09439510239" velocity="3.14159265359" />
        <safety_controller k_position="100" k_velocity="2" soft_lower_limit="-2.05948851735" soft_upper_limit="2.05948851735" />
        <dynamics damping="0.0" />
        <parent link="lwr_5_link" />
        <child link="lwr_6_link" />
    </joint>
    <gazebo reference="lwr_5_joint">
        <provideFeedback>1</provideFeedback>
        <implicitSpringDamper>1</implicitSpringDamper>
    </gazebo>
    <transmission name="lwr_5_trans" type="SimpleTransmission">
        <actuator name="lwr_5_motor" />
        <joint name="lwr_5_joint" />
        <mechanicalReduction>1.0</mechanicalReduction>
    </transmission>
    <link name="lwr_6_link">
        <inertial>
            <mass value="0.4000713156" />
            <origin rpy="0 0 0" xyz="0.0020739022 0.0586184696 -0.044799983" />
            <inertia ixx="0.0005278646" ixy="0.0000483" ixz="-0.0000375" iyy="0" iyz="-0.0010605344" izz="0.0034899625" />
        </inertial>
        <visual>
            <origin rpy="0 0 3.14159265359" xyz="0 0 0" />
            <geometry>
                <mesh filename="package://lwr_description/meshes/kuka/link_6.STL" />
            </geometry>
            <material name="Grey" />
        </visual>
        <collision>
            <origin rpy="0 0 3.14159265359" xyz="0 0 0" />
            <geometry>
                <mesh filename="model://kuka-lwr-4plus/meshes/convex/arm_wrist_convex.stl" scale="1.0 1.0 1.0" />
            </geometry>
        </collision>
    </link>
    <gazebo reference="lwr_6_link">
        <!--<material value="kuka-lwr.material"/>-->
    </gazebo>
    <joint name="lwr_6_joint" type="revolute">
        <origin rpy="0 0 0" xyz="0 0 0.078" />
        <axis xyz="0 0 1" />
        <limit effort="38" lower="-2.96705972839" upper="2.96705972839" velocity="3.14159265359" />
        <safety_controller k_position="100" k_velocity="2" soft_lower_limit="-2.93215314335" soft_upper_limit="2.93215314335" />
        <dynamics damping="0.0" />
        <parent link="lwr_6_link" />
        <child link="lwr_7_link" />
    </joint>
    <gazebo reference="lwr_6_joint">
        <provideFeedback>1</provideFeedback>
        <implicitSpringDamper>1</implicitSpringDamper>
    </gazebo>
    <transmission name="lwr_6_trans" type="SimpleTransmission">
        <actuator name="lwr_6_motor" />
        <joint name="lwr_6_joint" />
        <mechanicalReduction>1.0</mechanicalReduction>
    </transmission>
    <link name="lwr_7_link">
        <inertial>
            <mass value="0.6501439811" />
            <origin xyz="-0.0004601303 0.0014789221 0.0715608282" />
            <inertia ixx="0" ixy="-0.000000577" ixz="0" iyy="0.0000323" iyz="0" izz="0.0001187527" />
        </inertial>
        <visual>
            <origin rpy="0 0 0" xyz="0 0 0" />
            <geometry>
                <mesh filename="package://lwr_description/meshes/kuka/link_7.STL" />
            </geometry>
            <material name="Grey" />
        </visual>
        <collision>
            <origin rpy="0 0 0" xyz="0 0 0" />
            <geometry>
                <!--mesh filename="model://kuka-lwr-4plus/meshes/convex/arm_flanche_convex.stl" scale="1.0 1.0 1.0"/-->
                <mesh filename="model://kuka-lwr-4plus/meshes/arm_flanche.dae" scale="100 100 100" />
            </geometry>
            <surface>
                <friction>
                    <ode>
                        <mu>0.01</mu>
                        <mu2>0.01</mu2>
                    </ode>
                </friction>
            </surface>
        </collision>
    </link>
    <gazebo reference="lwr_7_link">
        <!--<material value="kuka-lwr.material"/>-->
    </gazebo>
    <!--joint name="lwr_hand_fixed_joint" type="fixed">
    <parent link="lwr_7_link"/>
    <child link="lwr_tool_mount"/>
  </joint>
  <link name="lwr_tool_mount"/-->
    <!--xacro:lwr_gazebo_controller namespace="" prefix="lwr" port="49938"/-->
    <origin xyz="0 0 0" rpy="0 -0 0" />
</robot>
