<robot name="single_lwr_robot">
  
  
  
  
  <material name="Kuka/DarkGrey">
    <color rgba="0.3 0.3 0.3 1.0" />
  </material>
  <material name="Kuka/LightGrey">
    <color rgba="0.8 0.8 0.8 1.0" />
  </material>
  <material name="Kuka/Red">
    <color rgba="0.3 0.3 0.3 1.0" />
  </material>
  <material name="Kuka/Black">
    <color rgba="0 0 0 1.0" />
  </material>
  <material name="Kuka/Orange">
    <color rgba="1.0 0.487 0 1.0" />
  </material>
  <material name="Kuka/Silver">
    <color rgba="1.0 1.0 1.0 1.0" />
  </material>
  <material name="Kuka/Grey">
    <color rgba="0.7 0.7 0.7 1.0" />
  </material>
  <material name="Kuka/Blue">
    <color rgba="0.0 0.0 0.8 1.0" />
  </material>
  
  
  
  
  
  <link name="box">
    <visual>
      <origin rpy="0 0 0" xyz="0 0 0.50" />
      <geometry>
        <box size="1.20 .74 1.0" />
      </geometry>
    </visual>
    <collision>
      <origin rpy="0 0 0" xyz="0 0 0.50" />
      <geometry>
        <box size="1.20 .74 1.0" />
      </geometry>
    </collision>
  </link>
  
  
  <joint name="box_lwr_base_joint" type="fixed">
    <origin rpy="0 0 0" xyz="-0.25 0 1" />
    <origin rpy="0 0 0" xyz="0 0 0" />
    <parent link="box" />
    <child link="lwr_base_link" />
  </joint>
  <link name="lwr_base_link">
    <inertial>
      <mass value="1.59410424227" />
      <origin xyz="0.0247176899493 -0.0048813356495 0.0880041493537" />
      <inertia ixx="-0.00484348232531" ixy="0.00530428584012" ixz="-0.0230532479697" iyy="-0.0722745110835" iyz="-0.0327431246372" izz="0.0512419485409" />
    </inertial>
    <visual>
      <origin rpy="0 0 3.14159265359" xyz="0 0 0" />
      <geometry>
        <mesh filename="package://lwr_description/meshes/base.STL" />
      </geometry>
      <material name="Kuka/Orange" />
    </visual>
    <collision>
      <origin rpy="0 0 3.14159265359" xyz="0 0 0.055" />
      <geometry>
        
        <cylinder length="0.11" radius="0.07" />
      </geometry>
    </collision>
  </link>
  
  <joint name="lwr_0_joint" type="revolute">
    <origin rpy="0 0 0" xyz="0 0 0.11" />
    <axis xyz="0 0 1" />
    <limit effort="176" lower="-2.96705972839" upper="2.96705972839" velocity="1.91986217719" />
    <dynamics damping="1.0" friction="10.0" />
    <parent link="lwr_base_link" />
    <child link="lwr_1_link" />
  </joint>
  <link name="lwr_1_link">
    <inertial>
      <mass value="2.59505949714" />
      <origin rpy="0 0 0" xyz="-0.0182798117509 -0.0954479442854 0.108893329193" />
      <inertia ixx="0.0969922803177" ixy="0.0482031571166" ixz="0.0103224312077" iyy="-0.00812120984846" iyz="-0.0493522877589" izz="-0.0935845533625" />
    </inertial>
    <visual>
      <origin rpy="0 0 3.14159265359" xyz="0 0 -0.008" />
      <geometry>
        <mesh filename="package://lwr_description/meshes/link_1.STL" />
      </geometry>
      <material name="Kuka/Orange" />
    </visual>
    <collision>
      <origin rpy="0 0 0" xyz="0 0 0.0" />
      <geometry>
        
        <sphere radius="0.07" />
      </geometry>
    </collision>
    <collision>
      <origin rpy="0 0 0" xyz="0 0.06 0.2" />
      <geometry>
        <sphere radius="0.07" />
      </geometry>
    </collision>
    <collision>
      <origin rpy="-0.291 0 0" xyz="0 0.03 0.1" />
      <geometry>
        <cylinder length="0.208" radius="0.07" />
      </geometry>
    </collision>
  </link>
  
  <joint name="lwr_1_joint" type="revolute">
    <origin rpy="0 0 0" xyz="0 0 0.2005" />
    <axis xyz="0 -1 0" />
    <limit effort="176" lower="-2.09439510239" upper="2.09439510239" velocity="1.91986217719" />
    <dynamics damping="1.0" friction="10.0" />
    <parent link="lwr_1_link" />
    <child link="lwr_2_link" />
  </joint>
  <link name="lwr_2_link">
    <inertial>
      <mass value="2.64307710289" />
      <origin rpy="0 0 0" xyz="0.0178483511019 0.0444617676412 0.0820684330467" />
      <inertia ixx="0.0298191515186" ixy="-0.00267587469462" ixz="-0.0723540051569" iyy="-0.0175062265033" iyz="0.0787099074197" izz="-0.024812872125" />
    </inertial>
    <visual>
      <origin rpy="0 0 3.14159265359" xyz="0 0 0.0" />
      <geometry>
        <mesh filename="package://lwr_description/meshes/link_2.STL" />
      </geometry>
      <material name="Kuka/Orange" />
    </visual>
    <collision>
      <origin rpy="0 0 0" xyz="0 0 0.2" />
      <geometry>
        
        <sphere radius="0.07" />
      </geometry>
    </collision>
    <collision>
      <origin rpy="0 0 0" xyz="0 -0.06 0.0" />
      <geometry>
        <sphere radius="0.07" />
      </geometry>
    </collision>
    <collision>
      <origin rpy="-0.291 0 0" xyz="0 -0.03 0.1" />
      <geometry>
        <cylinder length="0.208" radius="0.07" />
      </geometry>
    </collision>
  </link>
  
  <joint name="lwr_2_joint" type="revolute">
    <origin rpy="0 0 0" xyz="0 0 0.20" />
    <axis xyz="0 0 1" />
    <limit effort="100" lower="-2.96705972839" upper="2.96705972839" velocity="2.23402144255" />
    <dynamics damping="1.0" friction="10.0" />
    <parent link="lwr_2_link" />
    <child link="lwr_3_link" />
  </joint>
  <link name="lwr_3_link">
    <inertial>
      <mass value="2.77843455463" />
      <origin rpy="0 0 0" xyz="0.022517960727 0.0613605010705 0.161003638067" />
      <inertia ixx="0.0218570508958" ixy="0.0318031911928" ixz="0.00477477618464" iyy="-0.0708739532411" iyz="-0.0204850765334" izz="0.0805843300208" />
    </inertial>
    <visual>
      <origin rpy="0 0 3.14159265359" xyz="0 0 -0.008" />
      <geometry>
        <mesh filename="package://lwr_description/meshes/link_3.STL" />
      </geometry>
      <material name="Kuka/Orange" />
    </visual>
    <collision>
      <origin rpy="0 0 0" xyz="0 0 0.0" />
      <geometry>
        
        <sphere radius="0.07" />
      </geometry>
    </collision>
    <collision>
      <origin rpy="0 0 0" xyz="0 -0.06 0.2" />
      <geometry>
        <sphere radius="0.07" />
      </geometry>
    </collision>
    <collision>
      <origin rpy="0.291 0 0" xyz="0 -0.03 0.1" />
      <geometry>
        <cylinder length="0.208" radius="0.07" />
      </geometry>
    </collision>
  </link>
  
  <joint name="lwr_3_joint" type="revolute">
    <origin rpy="0 0 0" xyz="0 0 0.20" />
    <axis xyz="0 1 0" />
    <limit effort="100" lower="-2.09439510239" upper="2.09439510239" velocity="2.23402144255" />
    <dynamics damping="1.0" friction="10.0" />
    <parent link="lwr_3_link" />
    <child link="lwr_4_link" />
  </joint>
  <link name="lwr_4_link">
    <inertial>
      <mass value="2.67149058431" />
      <origin rpy="0 0 0" xyz="0.0219410778008 -0.04577654025 0.0609973617376" />
      <inertia ixx="-0.0205866536072" ixy="-0.0602214932412" ixz="0.0911445634434" iyy="-0.0538277179792" iyz="0.109967717328" izz="-0.0869219779457" />
    </inertial>
    <visual>
      <origin rpy="0 0 3.14159265359" xyz="0 0 0.0" />
      <geometry>
        <mesh filename="package://lwr_description/meshes/link_4.STL" />
      </geometry>
      <material name="Kuka/Orange" />
    </visual>
    <collision>
      <origin rpy="0 0 0" xyz="0 0 0.2" />
      <geometry>
        
        <sphere radius="0.07" />
      </geometry>
    </collision>
    <collision>
      <origin rpy="0 0 0" xyz="0 0.06 0.0" />
      <geometry>
        <sphere radius="0.07" />
      </geometry>
    </collision>
    <collision>
      <origin rpy="0.291 0 0" xyz="0 0.03 0.1" />
      <geometry>
        <cylinder length="0.208" radius="0.07" />
      </geometry>
    </collision>
  </link>
  
  <joint name="lwr_4_joint" type="revolute">
    <origin rpy="0 0 0" xyz="0 0 0.20" />
    <axis xyz="0 0 1" />
    <limit effort="100" lower="-2.96705972839" upper="2.96705972839" velocity="3.56047167407" />
    <dynamics damping="1.0" friction="10.0" />
    <parent link="lwr_4_link" />
    <child link="lwr_5_link" />
  </joint>
  <link name="lwr_5_link">
    <inertial>
      <mass value="1.68400461935" />
      <origin rpy="0 0 0" xyz="-0.0470583678531 -0.0637007831922 0.081162659719" />
      <inertia ixx="0.101738002416" ixy="0.0639731293487" ixz="-0.0166270168055" iyy="0.0166908057095" iyz="-0.0458984091861" izz="-0.0671643044148" />
    </inertial>
    <visual>
      <origin rpy="0 0 3.14159265359" xyz="0 0 -0.008" />
      <geometry name="lwr_5_geom">
        <mesh filename="package://lwr_description/meshes/link_5.STL" />
      </geometry>
      <material name="Kuka/Orange" />
    </visual>
    <collision>
      <origin rpy="0 0 0" xyz="0 0 0.0" />
      <geometry>
        
        <sphere radius="0.07" />
      </geometry>
    </collision>
    <collision>
      <origin rpy="0 0 0" xyz="0 0.04 0.19" />
      <geometry>
        <sphere radius="0.07" />
      </geometry>
    </collision>
    <collision>
      <origin rpy="-0.207 0 0" xyz="0 0.02 0.095" />
      <geometry>
        <cylinder length="0.198" radius="0.07" />
      </geometry>
    </collision>
  </link>
  
  <joint name="lwr_5_joint" type="revolute">
    <origin rpy="0 0 0" xyz="0 0 0.19" />
    <axis xyz="0 -1 0" />
    <limit effort="38" lower="-2.09439510239" upper="2.09439510239" velocity="3.21140582367" />
    <dynamics damping="1.0" friction="10.0" />
    <parent link="lwr_5_link" />
    <child link="lwr_6_link" />
  </joint>
  <link name="lwr_6_link">
    <inertial>
      <mass value="1.6359384941" />
      <origin rpy="0 0 0" xyz="-0.00543256884432 -0.0156916179303 0.0643253190949" />
      <inertia ixx="0.00721589522239" ixy="0.106204043658" ixz="-0.0292039335702" iyy="0.104707100721" iyz="-0.0234089058785" izz="-0.0677081039956" />
    </inertial>
    <visual>
      <origin rpy="0 0 3.14159265359" xyz="0 0 0" />
      <geometry>
        <mesh filename="package://lwr_description/meshes/link_6.STL" />
      </geometry>
      <material name="Kuka/Grey" />
    </visual>
    <collision>
      <origin rpy="0 0 3.14159265359" xyz="0 0 0" />
      <geometry>
        <mesh filename="package://lwr_description/meshes/convex/arm_wrist_convex.stl" />
      </geometry>
    </collision>
  </link>
  
  <joint name="lwr_6_joint" type="revolute">
    <origin rpy="0 0 0" xyz="0 0 0.078" />
    <axis xyz="0 0 1" />
    <limit effort="38" lower="-2.96705972839" upper="2.96705972839" velocity="3.21140582367" />
    <dynamics damping="1.0" friction="10.0" />
    <parent link="lwr_6_link" />
    <child link="lwr_7_link" />
  </joint>
  <link name="lwr_7_link">
    <inertial>
      <mass value="0.281663251487" />
      <origin xyz="-0.0887769570198 0.0330770483975 -0.133058119014" />
      <inertia ixx="-0.0570420812471" ixy="0.0166536963072" ixz="0.00108926156941" iyy="0.108264382153" iyz="0.0211589899856" izz="0.092733540876" />
    </inertial>
    <visual>
      <origin rpy="0 0 3.14159265359" xyz="0 0 0" />
      <geometry>
        <mesh filename="package://lwr_description/meshes/link_7.STL" />
      </geometry>
      <material name="Kuka/DarkGrey" />
    </visual>
    <collision>
      <origin rpy="0 0 3.14159265359" xyz="0 0 0" />
      <geometry>
        <cylinder length="0.05" radius="0.04" />
      </geometry>
    </collision>
  </link>
  <transmission name="lwr_0_trans">
    <type>transmission_interface/SimpleTransmission</type>
    <joint name="lwr_0_joint">
      <hardwareInterface>PositionJointInterface</hardwareInterface>
      <hardwareInterface>EffortJointInterface</hardwareInterface>
    </joint>
    <actuator name="lwr_0_motor">
      <mechanicalReduction>1</mechanicalReduction>
    </actuator>
  </transmission>
  <transmission name="lwr_1_trans">
    <type>transmission_interface/SimpleTransmission</type>
    <joint name="lwr_1_joint">
      <hardwareInterface>PositionJointInterface</hardwareInterface>
      <hardwareInterface>EffortJointInterface</hardwareInterface>
    </joint>
    <actuator name="lwr_1_motor">
      <mechanicalReduction>1</mechanicalReduction>
    </actuator>
  </transmission>
  <transmission name="lwr_2_trans">
    <type>transmission_interface/SimpleTransmission</type>
    <joint name="lwr_2_joint">
      <hardwareInterface>PositionJointInterface</hardwareInterface>
      <hardwareInterface>EffortJointInterface</hardwareInterface>
    </joint>
    <actuator name="lwr_2_motor">
      <mechanicalReduction>1</mechanicalReduction>
    </actuator>
  </transmission>
  <transmission name="lwr_3_trans">
    <type>transmission_interface/SimpleTransmission</type>
    <joint name="lwr_3_joint">
      <hardwareInterface>PositionJointInterface</hardwareInterface>
      <hardwareInterface>EffortJointInterface</hardwareInterface>
    </joint>
    <actuator name="lwr_3_motor">
      <mechanicalReduction>1</mechanicalReduction>
    </actuator>
  </transmission>
  <transmission name="lwr_4_trans">
    <type>transmission_interface/SimpleTransmission</type>
    <joint name="lwr_4_joint">
      <hardwareInterface>PositionJointInterface</hardwareInterface>
      <hardwareInterface>EffortJointInterface</hardwareInterface>
    </joint>
    <actuator name="lwr_4_motor">
      <mechanicalReduction>1</mechanicalReduction>
    </actuator>
  </transmission>
  <transmission name="lwr_5_trans">
    <type>transmission_interface/SimpleTransmission</type>
    <joint name="lwr_5_joint">
      <hardwareInterface>PositionJointInterface</hardwareInterface>
      <hardwareInterface>EffortJointInterface</hardwareInterface>
    </joint>
    <actuator name="lwr_5_motor">
      <mechanicalReduction>1</mechanicalReduction>
    </actuator>
  </transmission>
  <transmission name="lwr_6_trans">
    <type>transmission_interface/SimpleTransmission</type>
    <joint name="lwr_6_joint">
      <hardwareInterface>PositionJointInterface</hardwareInterface>
      <hardwareInterface>EffortJointInterface</hardwareInterface>
    </joint>
    <actuator name="lwr_6_motor">
      <mechanicalReduction>1</mechanicalReduction>
    </actuator>
  </transmission>
</robot>