<robot name="twoLinks">
    <link name="base_link" />
   <joint name="base_fixed_joint" type="fixed">
        <parent link="base_link" />
        <child link="link1" />
        <origin xyz="0 0 0" rpy="0 -0 0" />
        <axis xyz="0 0 0" />
    </joint>
    <link name="link1">
        <inertial>
            <mass value="1" />
            <inertia ixx="0.01" ixy="0.0" ixz="0.0" iyy="0.01" iyz="0.0" izz="0.01" />
        </inertial>
    </link>
    <joint name="joint_1_2" type="revolute">
        <parent link="link1" />
        <child link="link2" />
        <origin xyz="1 0 0" rpy="0 -0 0" />
        <axis xyz="0 0 1" />
        <limit effort="15" lower="-2.96705972839" upper="2.96705972839" velocity="1.91986217719"/>
    </joint>
    <link name="link2">
        <inertial>
            <mass value="1" />
            <inertia ixx="0.01" ixy="0.0" ixz="0.0" iyy="0.01" iyz="0.0" izz="0.01" />
            <origin xyz="1 0 0" rpy="0 -0 0" />
        </inertial>
    </link>
    <sensor name="dummy_accl1" type="accelerometer">
        <parent link="link1"/>
        <origin xyz="0.01 0.0 0.0" rpy="1.0 0.0 0.0" />
    </sensor> 
     <sensor name="dummy_gyro" type="gyroscope">
        <parent link="link2"/>
        <origin xyz="0 -0.01 +0.01" rpy="0 -0 0"/>
    </sensor>
    <sensor name="dummy_accl2" type="accelerometer">
        <parent link="link2"/>
        <origin xyz="0.1 0.0 0.0" rpy="0.0 0.0 0.0" />
    </sensor>
</robot>
